Workbook

Sheet Summary
A1: Marvin Bot bill of materials
A2: This workbook is the BOM's source of truth; copy it to track your own build. Set each line's status to to buy, ordered or owned and the totals follow. After editing, run python tools/bom/book.py to tidy it. Prices are indicative: see each line's price basis and the Sourcing sheet.
A4: Group | B4: Lines | C4: Total USD | D4: Owned USD | E4: Ordered USD | F4: To buy USD
A5: Actuators | B5: =COUNTA('Actuators'!A2:A6) -> 5 | C5: ='Actuators'!H8 -> 6200.98 | D5: =SUMIFS('Actuators'!$H$2:$H$6,'Actuators'!$D$2:$D$6,"owned") -> 0 | E5: =SUMIFS('Actuators'!$H$2:$H$6,'Actuators'!$D$2:$D$6,"ordered") -> 0 | F5: =SUMIFS('Actuators'!$H$2:$H$6,'Actuators'!$D$2:$D$6,"to buy") -> 6200.98
A6: Hands | B6: =COUNTA('Hands'!A2:A4) -> 3 | C6: ='Hands'!H6 -> 224 | D6: =SUMIFS('Hands'!$H$2:$H$4,'Hands'!$D$2:$D$4,"owned") -> 198 | E6: =SUMIFS('Hands'!$H$2:$H$4,'Hands'!$D$2:$D$4,"ordered") -> 0 | F6: =SUMIFS('Hands'!$H$2:$H$4,'Hands'!$D$2:$D$4,"to buy") -> 26
A7: Compute & sensors | B7: =COUNTA('Compute & sensors'!A2:A6) -> 5 | C7: ='Compute & sensors'!H8 -> 4723 | D7: =SUMIFS('Compute & sensors'!$H$2:$H$6,'Compute & sensors'!$D$2:$D$6,"owned") -> 3534 | E7: =SUMIFS('Compute & sensors'!$H$2:$H$6,'Compute & sensors'!$D$2:$D$6,"ordered") -> 0 | F7: =SUMIFS('Compute & sensors'!$H$2:$H$6,'Compute & sensors'!$D$2:$D$6,"to buy") -> 1189
A8: Power | B8: =COUNTA('Power'!A2:A15) -> 14 | C8: ='Power'!H17 -> 1633.05 | D8: =SUMIFS('Power'!$H$2:$H$15,'Power'!$D$2:$D$15,"owned") -> 0 | E8: =SUMIFS('Power'!$H$2:$H$15,'Power'!$D$2:$D$15,"ordered") -> 0 | F8: =SUMIFS('Power'!$H$2:$H$15,'Power'!$D$2:$D$15,"to buy") -> 1633.05
A9: Electronics & wiring | B9: =COUNTA('Electronics & wiring'!A2:A11) -> 10 | C9: ='Electronics & wiring'!H13 -> 808 | D9: =SUMIFS('Electronics & wiring'!$H$2:$H$11,'Electronics & wiring'!$D$2:$D$11,"owned") -> 0 | E9: =SUMIFS('Electronics & wiring'!$H$2:$H$11,'Electronics & wiring'!$D$2:$D$11,"ordered") -> 0 | F9: =SUMIFS('Electronics & wiring'!$H$2:$H$11,'Electronics & wiring'!$D$2:$D$11,"to buy") -> 808
A10: Structure & materials | B10: =COUNTA('Structure & materials'!A2:A14) -> 13 | C10: ='Structure & materials'!H16 -> 2582 | D10: =SUMIFS('Structure & materials'!$H$2:$H$14,'Structure & materials'!$D$2:$D$14,"owned") -> 0 | E10: =SUMIFS('Structure & materials'!$H$2:$H$14,'Structure & materials'!$D$2:$D$14,"ordered") -> 0 | F10: =SUMIFS('Structure & materials'!$H$2:$H$14,'Structure & materials'!$D$2:$D$14,"to buy") -> 2582
A11: Fasteners | B11: =COUNTA('Fasteners'!A2:A2) -> 1 | C11: ='Fasteners'!H4 -> 180 | D11: =SUMIFS('Fasteners'!$H$2:$H$2,'Fasteners'!$D$2:$D$2,"owned") -> 0 | E11: =SUMIFS('Fasteners'!$H$2:$H$2,'Fasteners'!$D$2:$D$2,"ordered") -> 0 | F11: =SUMIFS('Fasteners'!$H$2:$H$2,'Fasteners'!$D$2:$D$2,"to buy") -> 180
A12: Tooling | B12: =COUNTA('Tooling'!A2:A6) -> 5 | C12: ='Tooling'!H8 -> 710 | D12: =SUMIFS('Tooling'!$H$2:$H$6,'Tooling'!$D$2:$D$6,"owned") -> 0 | E12: =SUMIFS('Tooling'!$H$2:$H$6,'Tooling'!$D$2:$D$6,"ordered") -> 0 | F12: =SUMIFS('Tooling'!$H$2:$H$6,'Tooling'!$D$2:$D$6,"to buy") -> 710
A13: Safety | B13: =COUNTA('Safety'!A2:A5) -> 4 | C13: ='Safety'!H7 -> 470 | D13: =SUMIFS('Safety'!$H$2:$H$5,'Safety'!$D$2:$D$5,"owned") -> 0 | E13: =SUMIFS('Safety'!$H$2:$H$5,'Safety'!$D$2:$D$5,"ordered") -> 0 | F13: =SUMIFS('Safety'!$H$2:$H$5,'Safety'!$D$2:$D$5,"to buy") -> 470
A14: Total (full cost to replicate) | B14: =SUM(B5:B13) -> 60 | C14: =SUM(C5:C13) -> 17531.03 | D14: =SUM(D5:D13) -> 3732 | E14: =SUM(E5:E13) -> 0 | F14: =SUM(F5:F13) -> 13799.03
A16: Optional, not counted: a desktop RTX GPU with 24-32 GB for training and GR00T fine-tuning (RTX 5090: $1,999 list, about $4,000 or more street price in late 2026). Also not counted: the desktop CNC mill and 3D printer, shipping, import duties and tariffs.

Sheet Actuators
A1: ID | B1: Item | C1: Model | D1: Status | E1: Qty | F1: Spares | G1: Unit USD | H1: Line USD | I1: Price basis | J1: Source | K1: Notes
A2: sts3250 | B2: Feetech STS3250 serial-bus servo | C2: STS3250 | D2: to buy | E2: 4 | F2: 0 | G2: 97 | H2: =(E2+F2)*G2 -> 388 | I2: 2026-10-29: $97 (AIFit Lab, ST-3250-C001, backordered); $125 elsewhere (sold out) | J2: https://aifitlab.com/products/feetech-sts3250-servo-motor | K2: neck yaw/pitch and wrist pitch; check the variant (C001 or C002) before ordering
A3: rs00 | B3: Robstride RS00 14 N·m actuator | C3: RS00 | D3: to buy | E3: 2 | F3: 0 | G3: 138.99 | H3: =(E3+F3)*G3 -> 277.98 | I3: Seeed 2026-10-29: $138.99 each, $131.99 at 10+, in stock (RobStride list $125) | J3: https://www.seeedstudio.com/Robostride-00-Actuator-p-6664.html | K3: wrist yaw
A4: rs03 | B4: Robstride RS03 60 N·m actuator | C4: RS03 | D4: to buy | E4: 11 | F4: 1 | G4: 225 | H4: =(E4+F4)*G4 -> 2700 | I4: Seeed 2026-10-29: $225 each, $214 at 10+, in stock (RobStride list $225) | J4: https://www.seeedstudio.com/Robostride-03-Actuator-p-6774.html | K4: hip yaw and the two ankle motors, both legs; waist yaw; shoulder pitch and roll. Buy one first for the actuator bench test; 10 or more in one order get Seeed's $214 price
A5: rs04 | B5: Robstride RS04 120 N·m actuator | C5: RS04 | D5: to buy | E5: 6 | F5: 1 | G5: 255 | H5: =(E5+F5)*G5 -> 1785 | I5: Seeed 2026-10-29: $255 each, $242 at 10+, in stock (RobStride list $255) | J5: https://www.seeedstudio.com/Robostride-04-Actuator-p-6775.html | K5: hip pitch, hip roll and knee, both legs; buy one first for the actuator bench test
A6: rs06 | B6: Robstride RS06 36 N·m actuator | C6: RS06 | D6: to buy | E6: 4 | F6: 1 | G6: 210 | H6: =(E6+F6)*G6 -> 1050 | I6: Seeed 2026-10-29: $210 each, $200 at 10+, in stock (RobStride list $210) | J6: https://www.seeedstudio.com/Robostride-06-Actuator-p-6668.html | K6: shoulder yaw and elbow
B8: Total actuators | H8: =SUM(H2:H6) -> 6200.98

Sheet Hands
A1: ID | B1: Item | C1: Model | D1: Status | E1: Qty | F1: Spares | G1: Unit USD | H1: Line USD | I1: Price basis | J1: Source | K1: Notes
A2: hand-kit | B2: AmazingHand open-source 8-DOF four-finger hand kit, left and right (8 Feetech SCS0009 servos each, 5 V) | D2: owned | E2: 2 | F2: 0 | G2: 99 | H2: =(E2+F2)*G2 -> 198 | I2: Seeed 2026-10-29: $99 each, $97 at 10+, in stock; SKUs 100062181 (left), 100063642 (right) | J2: https://www.seeedstudio.com/Amazing-Hand-Open-Source-3D-Printable-Robotic-Hand-Kit.html | K2: owned by this build; the listing does not say what is in the box, so check that servos are included. 0.40 kg each as published (weigh); its design is CC-BY-4.0, see ACKNOWLEDGMENTS.md
A3: dcdc-hand | B3: DC-DC 12 V to 5 V, 3 A, small (in the wrist) | D3: to buy | E3: 2 | F3: 0 | G3: 8 | H3: =(E3+F3)*G3 -> 16 | I3: estimate | K3: one per hand: 8 SCS0009 servos at up to 0.3 A each
A4: servo-adapter-hand | B4: Feetech serial-bus USB adapter (Waveshare Bus Servo Adapter (A) class) | D4: to buy | E4: 2 | F4: 0 | G4: 5 | H4: =(E4+F4)*G4 -> 10 | I4: Waveshare 2026-10-29: $4.99 (SKU 25514) | J4: https://www.waveshare.com/bus-servo-adapter-a.htm | K4: one bus per hand: SCS0009 servos use Feetech's SCS protocol, the STS3250s its STS protocol; the hand kit's own driver board may do instead
B6: Total hands | H6: =SUM(H2:H4) -> 224

Sheet Compute & sensors
A1: ID | B1: Item | C1: Model | D1: Status | E1: Qty | F1: Spares | G1: Unit USD | H1: Line USD | I1: Price basis | J1: Source | K1: Notes
A2: compute | B2: Jetson AGX Orin 64 GB developer kit | D2: owned | E2: 1 | F2: 0 | G2: 3499 | H2: =(E2+F2)*G2 -> 3499 | I2: NVIDIA list price since July 2026 (was $1,999); SparkFun 2026-10-29: $3,499, backorder | J2: https://marketplace.nvidia.com/en-us/enterprise/robotics-edge/jetson-agx-orin-developer-kit/ | K2: owned by this build; a replicator buys it
A3: imu-backup | B3: Low-cost USB AHRS IMU | D3: owned | E3: 1 | F3: 0 | G3: 35 | H3: =(E3+F3)*G3 -> 35 | I3: estimate | K3: backup IMU and bench use
A4: nvme | B4: NVMe SSD, 1 TB, M.2 2280 | D4: to buy | E4: 1 | F4: 0 | G4: 100 | H4: =(E4+F4)*G4 -> 100 | I4: estimate | K4: the dev kit's 64 GB eMMC is too small for logs and datasets
A5: camera | B5: Orbbec Gemini 335L depth camera | D5: to buy | E5: 1 | F5: 0 | G5: 359 | H5: =(E5+F5)*G5 -> 359 | I5: Orbbec store list $359 (store page rate-limited 2026-10-29); RobotShop US $413 with tariffs | J5: https://store.orbbec.com/products/gemini-335l | K5: check the JetPack 7.2 driver before ordering
A6: imu | B6: Primary IMU (industrial AHRS; or BMI088 on a microcontroller) | D6: to buy | E6: 1 | F6: 0 | G6: 730 | H6: =(E6+F6)*G6 -> 730 | I6: distributor 2026-10 | K6: decide after bench test; the existing USB AHRS IMU is the backup
B8: Total compute & sensors | H8: =SUM(H2:H6) -> 4723

Sheet Power
A1: ID | B1: Item | C1: Model | D1: Status | E1: Qty | F1: Spares | G1: Unit USD | H1: Line USD | I1: Price basis | J1: Source | K1: Notes
A2: charger | B2: 13S charger adjustable to 4.1 V per cell | D2: to buy | E2: 1 | F2: 0 | G2: 300 | H2: =(E2+F2)*G2 -> 300 | I2: reseller 2026-10 | K2: daily charging at 4.1 V per cell
A3: bms | B3: 13S smart BMS 150 A with CAN telemetry | D3: to buy | E3: 1 | F3: 0 | G3: 145 | H3: =(E3+F3)*G3 -> 145 | I3: 2026-10-29: JK 8-24S 150 A $145 (18650 Battery Store, sold out); Daly 13S 150 A with CAN also sold | J3: https://www.18650batterystore.com/products/jk-b2a24s15p-bms | K3: check its CAN protocol and precharge support
A4: psu-bench | B4: 48 V 20 A bench power supply | D4: to buy | E4: 1 | F4: 0 | G4: 250 | H4: =(E4+F4)*G4 -> 250 | I4: estimate | K4: for bench and gantry tests
A5: batt-conn | B5: Anti-spark blind-mate battery connector (AS150 class) | D5: to buy | E5: 2 | F5: 0 | G5: 15 | H5: =(E5+F5)*G5 -> 30 | I5: estimate | K5: one on the pack and one on the cradle
A6: fuse | B6: Class-T fuse 100-125 A with holder; limb branch fuses | D6: to buy | E6: 1 | F6: 0 | G6: 60 | H6: =(E6+F6)*G6 -> 60 | I6: estimate
A7: dcdc-servo | B7: DC-DC 48 V to 12 V, 10 A, compact (at most 60 x 34 x 25 mm) | D7: to buy | E7: 1 | F7: 0 | G7: 60 | H7: =(E7+F7)*G7 -> 60 | I7: estimate | K7: the pelvis channel under the waist motor has room for 60 x 34 x 25 mm; a chassis-mount 150 W module does not fit
A8: dcdc-compute | B8: DC-DC 75 V-input to 19-20 V; at least 120 W (computer) | D8: to buy | E8: 1 | F8: 0 | G8: 80 | H8: =(E8+F8)*G8 -> 80 | I8: estimate | K8: upstream of the contactor
A9: ideal-diode | B9: Ideal-diode OR circuit (LTC4359 class) for the computer rail | D9: to buy | E9: 1 | F9: 0 | G9: 40 | H9: =(E9+F9)*G9 -> 40 | I9: estimate
A10: keepalive | B10: Keep-alive battery 50-100 Wh for the computer | D10: to buy | E10: 1 | F10: 0 | G10: 80 | H10: =(E10+F10)*G10 -> 80 | I10: estimate | K10: lets the computer stay up during a pack swap
A11: contactor | B11: Main contactor (48 V DC rated) | D11: to buy | E11: 1 | F11: 0 | G11: 60 | H11: =(E11+F11)*G11 -> 60 | I11: estimate | K11: opened by the e-stop chain
A12: cells | B12: Molicel P45B 21700 cells | D12: to buy | E12: 39 | F12: 0 | G12: 9.95 | H12: =(E12+F12)*G12 -> 388.05 | I12: 2026-10-29: $9.95 (Batteries in a Flash, in stock); 18650 Battery Store $9.99 regular | J12: https://www.18650batterystore.com/products/molicel-p45b | K12: 13S3P pack ~630 Wh; buy from an authorised dealer
A13: pack-hw | B13: Pack housing; nickel strip; quick-release cradle | D13: to buy | E13: 1 | F13: 0 | G13: 80 | H13: =(E13+F13)*G13 -> 80 | I13: estimate
A14: precharge | B14: Precharge resistor and relay | D14: to buy | E14: 1 | F14: 0 | G14: 20 | H14: =(E14+F14)*G14 -> 20 | I14: estimate
A15: regen-clamp | B15: Regen clamp (brake resistor chopper or TVS ~56-58 V) | D15: to buy | E15: 1 | F15: 0 | G15: 40 | H15: =(E15+F15)*G15 -> 40 | I15: estimate | K15: needed whenever a bench supply is used
B17: Total power | H17: =SUM(H2:H15) -> 1633.05

Sheet Electronics & wiring
A1: ID | B1: Item | C1: Model | D1: Status | E1: Qty | F1: Spares | G1: Unit USD | H1: Line USD | I1: Price basis | J1: Source | K1: Notes
A2: can-xcvr | B2: 3.3 V CAN transceiver boards for the Orin's on-board CAN | D2: to buy | E2: 2 | F2: 0 | G2: 10 | H2: =(E2+F2)*G2 -> 20 | I2: estimate | K2: arm buses
A3: usb-hub | B3: Compact USB 3 hub, 4-port | D3: to buy | E3: 1 | F3: 0 | G3: 30 | H3: =(E3+F3)*G3 -> 30 | I3: estimate | K3: the dev kit has 4 USB-A and 2 USB-C ports; the robot uses 3 CAN adapters, 3 servo adapters, the camera, the IMU and the gamepad receiver
A4: servo-adapter | B4: Feetech serial-bus USB adapter (Waveshare Bus Servo Adapter (A) class) | D4: to buy | E4: 1 | F4: 0 | G4: 5 | H4: =(E4+F4)*G4 -> 5 | I4: Waveshare 2026-10-29: $4.99 (SKU 25514) | J4: https://www.waveshare.com/bus-servo-adapter-a.htm | K4: STS3250 bus (neck and wrist pitch)
A5: can-usb-dual | B5: Isolated USB-CAN adapter, dual channel (InnoMaker USB2CAN-X2 class; SocketCAN) | D5: to buy | E5: 2 | F5: 0 | G5: 130 | H5: =(E5+F5)*G5 -> 260 | I5: unconfirmed 2026-10-29: no live US listing found; ~$126 (AED 462) at a UAE marketplace | J5: https://github.com/INNO-MAKER/usb2can | K5: one per leg (hip and shank buses), 3 kV isolation per its manual; with can-usb-batt and the Orin's two on-board ports (arm buses) this covers all 7 CAN buses in robot.yaml in the 3 adapter outlines of the electronics bay
A6: can-usb-single | B6: Isolated USB-CAN adapter, single channel (CANable Pro class; candleLight / gs_usb) | D6: to buy | E6: 2 | F6: 0 | G6: 60 | H6: =(E6+F6)*G6 -> 120 | I6: reseller listing 2026-10-29, unverified: CANable Pro $60, Pro 1.1 (5 kV) $70 | J6: https://reach.dog/shop/openlight-labs/products/canable-pro-isolated-usb-to-can-adapter | K6: one for the battery (BMS) bus, one for the actuator bench rig
A7: limb-conn | B7: Limb-root connectors: XT60-class power pair and latching signal pair, per limb | D7: to buy | E7: 4 | F7: 0 | G7: 12 | H7: =(E7+F7)*G7 -> 48 | I7: estimate | K7: on the bulkheads beside each limb's first flange
A8: can-robstride-dbg | B8: RobStride USB-to-CAN debug adapter (official GUI tool) | D8: to buy | E8: 1 | F8: 0 | G8: 15 | H8: =(E8+F8)*G8 -> 15 | I8: Seeed listing 2026-10, unverified: $15 each, $14 at 10+ | J8: https://www.seeedstudio.com/Robostride-CAN-USB-Driver-Board-p-6708.html | K8: for RobStride's configuration GUI (IDs, firmware); check whether it works as a SocketCAN bus before using it on the robot
A9: harness | B9: Silicone wire; connectors; strain relief; sleeving | D9: to buy | E9: 1 | F9: 0 | G9: 200 | H9: =(E9+F9)*G9 -> 200 | I9: estimate
A10: can-cable | B10: Twisted-pair CAN cable, connectors and 120 Ω terminations | D10: to buy | E10: 1 | F10: 0 | G10: 50 | H10: =(E10+F10)*G10 -> 50 | I10: estimate
A11: gamepad | B11: Wireless gamepad | D11: to buy | E11: 1 | F11: 0 | G11: 60 | H11: =(E11+F11)*G11 -> 60 | I11: estimate
B13: Total electronics & wiring | H13: =SUM(H2:H11) -> 808

Sheet Structure & materials
A1: ID | B1: Item | C1: Model | D1: Status | E1: Qty | F1: Spares | G1: Unit USD | H1: Line USD | I1: Price basis | J1: Source | K1: Notes
A2: alu-6061 | B2: 6061-T6 aluminium plate and bar stock | D2: to buy | E2: 1 | F2: 0 | G2: 300 | H2: =(E2+F2)*G2 -> 300 | I2: estimate | K2: leg cores and brackets for both legs; about 6 kg of finished CNC 6061 across the robot (build_parts.csv)
A3: bearing-6806 | B3: 6806-2RS thin-section ball bearing (30 x 42 x 7 mm) for far-side joint support | D3: to buy | E3: 6 | F3: 0 | G3: 10 | H3: =(E3+F3)*G3 -> 60 | I3: 2026-10-29: $6.45 (Zoro, 61806-2RS) to CA$25.68 (VXB); budget grades ~$8 | J3: https://www.zoro.com/ezo-deep-groove-30mm-bore-42mm-od-sealed-6806-2rsc0srl/i/G2080051 | K3: hip roll, hip pitch and knee, both legs
A4: alu-7075 | B4: 7075-T6 bar for highly loaded flanges and ankle cranks | D4: to buy | E4: 1 | F4: 0 | G4: 100 | H4: =(E4+F4)*G4 -> 100 | I4: estimate
A5: materials-upper | B5: Aluminium and filament for torso; arms; head | D5: to buy | E5: 1 | F5: 0 | G5: 250 | H5: =(E5+F5)*G5 -> 250 | I5: estimate
A6: push-rods | B6: Ankle push rods (steel tube with threaded inserts) | D6: to buy | E6: 4 | F6: 0 | G6: 10 | H6: =(E6+F6)*G6 -> 40 | I6: estimate | K6: two per ankle
A7: fil-cfnylon | B7: Carbon-fibre nylon filament (kg) | D7: to buy | E7: 4 | F7: 0 | G7: 95 | H7: =(E7+F7)*G7 -> 380 | I7: typical first-party price 2026-10 | K7: structural shells; needs a hardened nozzle and dry storage
A8: crossed-roller | B8: Crossed-roller bearing for the waist | D8: to buy | E8: 1 | F8: 0 | G8: 80 | H8: =(E8+F8)*G8 -> 80 | I8: reseller range $20-80
A9: rod-ends | B9: M6 steel-ball rod ends for ankle push rods | D9: to buy | E9: 8 | F9: 0 | G9: 8 | H9: =(E9+F9)*G9 -> 64 | I9: estimate | K9: two per push rod; size from simulated linkage loads
A10: machining-pelvis | B10: Online machining: pelvis back (20 mm, 3D), pelvis top and two gussets (6 mm plates) | D10: to buy | E10: 1 | F10: 0 | G10: 400 | H10: =(E10+F10)*G10 -> 400 | I10: estimate, not quoted (typical online CNC price) | K10: too large for a desktop mill; process "service" in build_parts.csv
A11: machining-legs | B11: Online machining: shin inner and outer plates, foot bases (6 pocketed 4-5 mm 6061 plates) | D11: to buy | E11: 1 | F11: 0 | G11: 450 | H11: =(E11+F11)*G11 -> 450 | I11: estimate, not quoted (typical online CNC price for pocketed plates) | K11: too large for a desktop mill; process "service" in build_parts.csv
A12: machining-torso | B12: Online machining: two torso uprights (25 mm 6061; 3D) | D12: to buy | E12: 1 | F12: 0 | G12: 350 | H12: =(E12+F12)*G12 -> 350 | I12: estimate, not quoted (typical online CNC price) | K12: too large for a desktop mill; process "service" in build_parts.csv
A13: fil-petgcf | B13: PETG-CF filament (kg) | D13: to buy | E13: 2 | F13: 0 | G13: 33 | H13: =(E13+F13)*G13 -> 66 | I13: typical price 2026-10 | K13: jigs and non-structural parts
A14: fil-tpu | B14: TPU 95A filament (kg) | D14: to buy | E14: 1 | F14: 0 | G14: 42 | H14: =(E14+F14)*G14 -> 42 | I14: typical price 2026-10 | K14: soles and bumpers
B16: Total structure & materials | H16: =SUM(H2:H14) -> 2582

Sheet Fasteners
A1: ID | B1: Item | C1: Model | D1: Status | E1: Qty | F1: Spares | G1: Unit USD | H1: Line USD | I1: Price basis | J1: Source | K1: Notes
A2: fasteners | B2: Metric fasteners; heat-set inserts; dowel pins; threadlocker | D2: to buy | E2: 1 | F2: 0 | G2: 180 | H2: =(E2+F2)*G2 -> 180 | I2: estimate | K2: includes the 348 actuator bolts in build_fasteners.csv (12.9 socket head, M3-M5)
B4: Total fasteners | H4: =SUM(H2:H2) -> 180

Sheet Tooling
A1: ID | B1: Item | C1: Model | D1: Status | E1: Qty | F1: Spares | G1: Unit USD | H1: Line USD | I1: Price basis | J1: Source | K1: Notes
A2: spot-welder | B2: Battery spot welder and pack supplies (fish paper, insulating rings, Kapton) | D2: to buy | E2: 1 | F2: 0 | G2: 150 | H2: =(E2+F2)*G2 -> 150 | I2: estimate | K2: or have the pack built by a battery shop
A3: endmills | B3: Carbide 3-flute end mills for aluminium (1/8 and 1/4 in) | D3: to buy | E3: 8 | F3: 0 | G3: 20 | H3: =(E3+F3)*G3 -> 160 | I3: reseller range $14-33
A4: hand-tools | B4: Hand tools: torque screwdriver and hex bits, crimp tools, multimeter, digital scale (5 kg x 1 g) | D4: to buy | E4: 1 | F4: 0 | G4: 200 | H4: =(E4+F4)*G4 -> 200 | I4: estimate | K4: the scale weighs parts against the mass budget; a desktop CNC mill and 3D printer are assumed and not counted
A5: print-tools | B5: Hardened-steel nozzle and filament dryer | D5: to buy | E5: 1 | F5: 0 | G5: 80 | H5: =(E5+F5)*G5 -> 80 | I5: estimate | K5: carbon-fibre nylon wears brass nozzles and must be printed dry
A6: leg-jig | B6: Single-leg test jig (aluminium extrusion) | D6: to buy | E6: 1 | F6: 0 | G6: 120 | H6: =(E6+F6)*G6 -> 120 | I6: estimate
B8: Total tooling | H8: =SUM(H2:H6) -> 710

Sheet Safety
A1: ID | B1: Item | C1: Model | D1: Status | E1: Qty | F1: Spares | G1: Unit USD | H1: Line USD | I1: Price basis | J1: Source | K1: Notes
A2: padding | B2: Fall padding foam | D2: to buy | E2: 1 | F2: 0 | G2: 50 | H2: =(E2+F2)*G2 -> 50 | I2: estimate
A3: gantry | B3: Gantry frame; harness and hoist | D3: to buy | E3: 1 | F3: 0 | G3: 300 | H3: =(E3+F3)*G3 -> 300 | I3: estimate
A4: estop-wired | B4: Latching e-stop button and contactor driver | D4: to buy | E4: 1 | F4: 0 | G4: 40 | H4: =(E4+F4)*G4 -> 40 | I4: estimate
A5: estop-rf | B5: Wireless e-stop: handheld transmitter; receiver and watchdog relay | D5: to buy | E5: 1 | F5: 0 | G5: 80 | H5: =(E5+F5)*G5 -> 80 | I5: estimate | K5: in series with the wired e-stop
B7: Total safety | H7: =SUM(H2:H5) -> 470

Sheet Sourcing
A1: ID | B1: Vendor | C1: Kind | D1: URL | E1: Unit USD | F1: Tiers | G1: Availability | H1: Checked | I1: Confirmed | J1: Notes
A2: bearing-6806 | B2: Simply Bearings | C2: distributor | D2: https://simplybearings.co.uk/shop/p170125/68062RS-Budget-Rubber-Sealed-Thin-Section-Deep-Groove-Ball-Bearing-30x42x7mm/product_info.html | F2: £6.33 ex VAT; £5.64 at 4+ | H2: 2026-10-29 | I2: yes | J2: budget grade
A3: bearing-6806 | B3: Zoro | C3: distributor | D3: https://www.zoro.com/ezo-deep-groove-30mm-bore-42mm-od-sealed-6806-2rsc0srl/i/G2080051 | H3: 2026-10-29 | I3: no | J3: EZO 6806-2RS; a 61806-2RS listing showed $6.45
A4: bms | B4: 18650 Battery Store | C4: dealer | D4: https://www.18650batterystore.com/products/jk-b2a24s15p-bms | E4: 145 | G4: sold out | H4: 2026-10-29 | I4: yes | J4: JK-B2A24S15P, 8-24S 150 A, 2 A active balancing; confirm its CAN protocol
A5: camera | B5: Orbbec store | C5: official | D5: https://store.orbbec.com/products/gemini-335l | E5: 359 | H5: 2026-10-29 | I5: no | J5: store page rate-limited; $359 is the list price shown by resellers
A6: camera | B6: RobotShop | C6: distributor | D6: https://www.robotshop.com/products/orbbec-gemini-335l-camera | E6: 413 | G6: 5 in stock | H6: 2026-10-29 | I6: yes | J6: includes US tariffs
A7: can-robstride-dbg | B7: Seeed Studio | C7: official reseller | D7: https://www.seeedstudio.com/Robostride-CAN-USB-Driver-Board-p-6708.html | E7: 15 | F7: $14 at 10+ | H7: 2026-10 | I7: no | J7: price from an earlier check; not reopened
A8: can-usb-dual | B8: Carrefour UAE marketplace | C8: marketplace | D8: https://www.carrefouruae.com/mafuae/en/miscellaneous/innomaker-dual-channels-usb-to-can-converter-for-raspberry-pi5-4-pi3b-pi3-pi-zero-w-jetson-nano-tinker-board-any-sbcs-desktop-laptop-support-windows-linux-mac-os-android-venus-os-/p/1881649107638 | E8: 126 | H8: 2026-10-29 | I8: no | J8: AED 462 incl. VAT; the only listing with a price
A9: can-usb-dual | B9: InnoMaker USB2CAN-X2 (docs) | C9: official | D9: https://github.com/INNO-MAKER/usb2can | H9: 2026-10-29 | I9: yes | J9: two channels, 3 kV isolation, SocketCAN; no live US price found
A10: can-usb-single | B10: Openlight Labs (CANable Pro) | C10: official | D10: https://reach.dog/shop/openlight-labs/products/canable-pro-isolated-usb-to-can-adapter | E10: 60 | H10: 2026-10-29 | I10: no | J10: Pro 1.1 (5 kV) $70; candleLight firmware gives gs_usb SocketCAN
A11: can-usb-single | B11: RobotShop (CANable Pro clone) | C11: distributor | D11: https://robotshop.com/products/eyou-robotics-can-usb-adapter-canable-pro | E11: 42 | H11: 2026-10-29 | I11: no | J11: third-party CANable Pro build
A12: cells | B12: 18650 Battery Store | C12: authorised dealer | D12: https://www.18650batterystore.com/products/molicel-p45b | E12: 9.99 | F12: sale $5.19 when in stock | G12: sold out | H12: 2026-10-29 | I12: yes | J12: regular price $9.99
A13: cells | B13: Batteries in a Flash | C13: dealer | D13: https://www.batteriesinaflash.com/regular-rechargeable-batteries/molicel-inr-21700-p45b-3-6-volt-4500mah-45a-lithium-ion-cell | E13: 9.95 | F13: $8.95 at 600+ | G13: in stock | H13: 2026-10-29 | I13: yes
A14: compute | B14: CNX Software (news) | C14: price report | D14: https://www.cnx-software.com/2026/07/22/nvidia-increases-the-price-of-jetson-modules-and-devkits-by-up-to-101/ | E14: 3499 | H14: 2026-10-29 | I14: yes | J14: source for the July 2026 price change
A15: compute | B15: NVIDIA Marketplace | C15: official | D15: https://marketplace.nvidia.com/en-us/enterprise/robotics-edge/jetson-agx-orin-developer-kit/ | E15: 3499 | G15: reported out of stock 2026-10-21 | H15: 2026-10-29 | I15: no | J15: page timed out; list price raised from $1,999 to $3,499 in July 2026 (NVIDIA developer FAQ, reported by CNX Software)
A16: compute | B16: SparkFun | C16: distributor | D16: https://www.sparkfun.com/nvidia-jetson-agx-orin-64gb-developer-kit.html | E16: 3499 | G16: backorder | H16: 2026-10-29 | I16: yes | J16: SKU DEV-22099
A17: dcdc-servo | B17: Bravo Electro | C17: distributor | D17: https://www.bravoelectro.com/ddr-120c-12.html | E17: 67.26 | F17: $61.24 at 10+ | H17: 2026-10-29 | I17: yes | J17: Mean Well DDR-120C-12 (33.6-67.2 V in, 12 V 10 A) is a DIN-rail module and too big for the pelvis channel; reference price only
A18: hand-kit | B18: Pollen Robotics AmazingHand | C18: open-source design | D18: https://github.com/pollen-robotics/AmazingHand | H18: 2026-10-29 | I18: yes | J18: bill of materials and print files for building the hand from parts (the project gives under €200 per hand, plus the control board)
A19: hand-kit | B19: Seeed Studio (left) | C19: official reseller | D19: https://www.seeedstudio.com/Amazing-Hand-Open-Source-3D-Printable-Robotic-Hand-Kit.html | E19: 99 | F19: $97 at 10+ | G19: in stock, China warehouse | H19: 2026-10-29 | I19: yes | J19: SKU 100062181; box contents not listed
A20: hand-kit | B20: Seeed Studio (right) | C20: official reseller | D20: https://www.seeedstudio.com/Amazing-Hand-Right-Hand-The-Open-Source-Robotic-Hand-Developer-Kit.html | E20: 99 | F20: $97 at 10+ | G20: in stock, China warehouse | H20: 2026-10-29 | I20: yes | J20: SKU 100063642; box contents not listed
A21: rs00 | B21: Seeed Studio | C21: official reseller | D21: https://www.seeedstudio.com/Robostride-00-Actuator-p-6664.html | E21: 138.99 | F21: $131.99 at 10+ | G21: in stock, China warehouse | H21: 2026-10-29 | I21: yes | J21: RobStride list $125
A22: rs03 | B22: Seeed Studio | C22: official reseller | D22: https://www.seeedstudio.com/Robostride-03-Actuator-p-6774.html | E22: 225 | F22: $214 at 10+ | G22: in stock, China warehouse | H22: 2026-10-29 | I22: yes
A23: rs04 | B23: Seeed Studio | C23: official reseller | D23: https://www.seeedstudio.com/Robostride-04-Actuator-p-6775.html | E23: 255 | F23: $242 at 10+ | G23: in stock, China warehouse; lead time not shown | H23: 2026-10-29 | I23: yes | J23: RobStride's own site links to Seeed and Amazon for ordering
A24: rs06 | B24: Seeed Studio | C24: official reseller | D24: https://www.seeedstudio.com/Robostride-06-Actuator-p-6668.html | E24: 210 | F24: $200 at 10+ | G24: in stock, China warehouse | H24: 2026-10-29 | I24: yes
A25: servo-adapter | B25: Feetech FE-URT-1 (RobotShop UK) | C25: distributor | D25: https://uk.robotshop.com/products/fe-urt-1-usb-to-ttl-485-bus-programmer | F25: £13.67 | G25: 1 left | H25: 2026-10-29 | I25: yes | J25: Feetech's own programmer; alternative
A26: servo-adapter | B26: Waveshare | C26: official | D26: https://www.waveshare.com/bus-servo-adapter-a.htm | E26: 4.99 | H26: 2026-10-29 | I26: yes | J26: Bus Servo Adapter (A) SKU 25514; supports ST and SC series
A27: sts3250 | B27: AIFit Lab | C27: reseller | D27: https://aifitlab.com/products/feetech-sts3250-servo-motor | E27: 97 | G27: backordered | H27: 2026-10-29 | I27: yes | J27: ST-3250-C001 with bracket
A28: sts3250 | B28: OpenELAB | C28: reseller | D28: https://openelab.io/products/feetech-sts3250-c002-servo-12v | F28: €75.85 | H28: 2026-10-29 | I28: yes | J28: STS3250-C002 variant (12 V, 50 kg·cm, 1:345); check it suits the neck and wrist
A29: sts3250 | B29: RCDrone | C29: reseller | D29: https://rcdrone.top/products/feetech-sts3250-servo-motor | E29: 125 | G29: sold out | H29: 2026-10-29 | I29: yes

Sheet Made parts (CAD)
A1: Part | B1: Qty | C1: Process | D1: Material | E1: Form | F1: Stock mm | G1: Mass g | H1: Size mm | I1: Notes | J1: Status | K1: Build notes
A2: elec_battery_socket | B2: 1 | C2: bought | D2: bought | G2: 15 | H2: 31 x 21 x 11 | I2: battery connector, cradle half (AS150 class), at the front of the battery bay | J2: to make
A3: elec_bulkhead_arm_{side} | B3: 2 | C3: bought | D3: bought | G3: 15 | H3: 30 x 28 x 10 | I3: arm power and signal connectors | J3: to make
A4: elec_bulkhead_leg_{side} | B4: 2 | C4: bought | D4: bought | G4: 15 | H4: 30 x 28 x 12 | I4: leg power (XT60 class) and signal connectors | J4: to make
A5: elec_can_usb_1 | B5: 1 | C5: bought | D5: bought | G5: 35 | H5: 60 x 22 x 12 | I5: isolated USB-CAN adapter | J5: to make
A6: elec_can_usb_2 | B6: 1 | C6: bought | D6: bought | G6: 35 | H6: 60 x 22 x 12 | I6: isolated USB-CAN adapter | J6: to make
A7: elec_can_usb_3 | B7: 1 | C7: bought | D7: bought | G7: 35 | H7: 60 x 22 x 12 | I7: isolated USB-CAN adapter | J7: to make
A8: elec_contactor | B8: 1 | C8: bought | D8: bought | G8: 180 | H8: 50 x 45 x 35 | I8: main contactor, 48 V DC, opened by the e-stop chain | J8: to make
A9: elec_dcdc_compute | B9: 1 | C9: bought | D9: bought | G9: 120 | H9: 60 x 40 x 13 | I9: DC-DC 48 V to 19-20 V, 120 W+, ahead of the contactor | J9: to make
A10: elec_dcdc_servo | B10: 1 | C10: bought | D10: bought | G10: 110 | H10: 60 x 34 x 25 | I10: DC-DC 48 V to 12 V, 10 A (servos) | J10: to make
A11: elec_estop_relay | B11: 1 | C11: bought | D11: bought | G11: 60 | H11: 40 x 35 x 14 | I11: wireless e-stop receiver and watchdog relay | J11: to make
A12: elec_harness_pelvis | B12: 1 | C12: bought | D12: bought | G12: 220 | H12: 10 x 10 x 10 | I12: harness allowance: pelvis (limb-root connectors on the bulkheads) | J12: to make
A13: elec_harness_torso | B13: 1 | C13: bought | D13: bought | G13: 270 | H13: 10 x 10 x 10 | I13: harness allowance: torso (limb-root connectors on the bulkheads) | J13: to make
... A17: elec_precharge | B17: 1 | C17: bought | D17: bought | G17: 30 | H17: 40 x 35 x 12 | I17: precharge resistor and relay, across the contactor | J17: to make
A18: head_camera | B18: 1 | C18: bought | D18: bought | G18: 133 | H18: 124 x 29 x 27 | J18: to make
A19: {side}_ankle_rod_a | B19: 2 | C19: bought | D19: bought | G19: 30 | H19: 91 x 20 x 11 | I19: steel tube with two M6 rod ends | J19: to make
A20: {side}_ankle_rod_b | B20: 2 | C20: bought | D20: bought | G20: 45 | H20: 191 x 50 x 11 | I20: steel tube with two M6 rod ends | J20: to make
A21: {side}_hand | B21: 2 | C21: bought | D21: bought | G21: 400 | H21: 170 x 134 x 119 | I21: AmazingHand by Pollen Robotics (CC-BY-4.0), description/third_party/amazing_hand | J21: to make
A22: {side}_hip_pitch_bearing | B22: 2 | C22: bought | D22: bought | G22: 25 | H22: 42 x 42 x 7 | I22: 6806-2RS far-side bearing | J22: to make
A23: {side}_hip_roll_bearing | B23: 2 | C23: bought | D23: bought | G23: 25 | H23: 42 x 42 x 7 | I23: 6806-2RS far-side bearing | J23: to make
A24: {side}_knee_bearing | B24: 2 | C24: bought | D24: bought | G24: 25 | H24: 42 x 42 x 7 | I24: 6806-2RS far-side bearing | J24: to make
A25: neck_bracket | B25: 1 | C25: cnc | D25: al6061 | E25: 3D | F25: 40 | G25: 84.6 | H25: 62 x 50 x 40 | J25: to make
A26: pelvis_roll_mount_{side} | B26: 2 | C26: cnc | D26: al6061 | E26: 3D | F26: 15 | G26: 45.9 | H26: 120 x 120 x 13 | J26: to make
A27: pelvis_waist_mount | B27: 1 | C27: cnc | D27: al6061 | E27: 3D | F27: 15 | G27: 54.1 | H27: 112 x 112 x 12 | J27: to make
A28: torso_base | B28: 1 | C28: cnc | D28: al6061 | E28: flat 6.0 mm | F28: 6 | G28: 236.2 | H28: 150 x 122 x 6 | J28: to make
A29: torso_battery_shelf | B29: 1 | C29: cnc | D29: al6061 | E29: flat 4.0 mm | F29: 4 | G29: 65.2 | H29: 146 x 60 x 4 | J29: to make
A30: torso_bridge | B30: 1 | C30: cnc | D30: al6061 | E30: flat 6.0 mm | F30: 6 | G30: 136.5 | H30: 116 x 112 x 6 | J30: to make
A31: torso_compute_plate | B31: 1 | C31: cnc | D31: al6061 | E31: flat 3.0 mm | F31: 3 | G31: 67 | H31: 128 x 104 x 3 | J31: to make
A32: torso_shoulder_plate_{side} | B32: 2 | C32: cnc | D32: al6061 | E32: flat 6.0 mm | F32: 6 | G32: 80.3 | H32: 142 x 129 x 6 | J32: to make
A33: torso_spacer_l0 | B33: 1 | C33: cnc | D33: al6061 | E33: flat 11.8 mm | F33: 12 | G33: 11.5 | H33: 20 x 20 x 12 | J33: to make
A34: torso_spacer_l1 | B34: 1 | C34: cnc | D34: al6061 | E34: flat 11.8 mm | F34: 12 | G34: 11.5 | H34: 20 x 20 x 12 | J34: to make
A35: torso_spacer_r0 | B35: 1 | C35: cnc | D35: al6061 | E35: flat 11.8 mm | F35: 12 | G35: 11.5 | H35: 20 x 20 x 12 | J35: to make
A36: torso_spacer_r1 | B36: 1 | C36: cnc | D36: al6061 | E36: flat 11.8 mm | F36: 12 | G36: 11.5 | H36: 20 x 20 x 12 | J36: to make
... A78: {side}_ankle_cross | B78: 2 | C78: cnc | D78: al7075 | E78: flat 30.0 mm | F78: 30 | G78: 85.6 | H78: 53 x 44 x 30 | J78: to make
A79: neck_cover | B79: 1 | C79: cover | D79: pa_cf | E79: 3D | G79: 40.6 | H79: 92 x 92 x 73 | J79: to make
A80: pelvis_cover | B80: 1 | C80: cover | D80: pa_cf | E80: 3D | G80: 42 | H80: 237 x 202 x 56 | J80: to make
A81: torso_cover_back_l_waist | B81: 1 | C81: cover | D81: pa_cf | E81: 3D | G81: 50.8 | H81: 174 x 100 x 87 | J81: to make
A82: torso_cover_back_r_waist | B82: 1 | C82: cover | D82: pa_cf | E82: 3D | G82: 50.8 | H82: 174 x 100 x 87 | J82: to make
A83: torso_cover_back_{side} | B83: 2 | C83: cover | D83: pa_cf | E83: 3D | G83: 61.1 | H83: 214 x 102 x 84 | J83: to make
A84: torso_cover_front_l_waist | B84: 1 | C84: cover | D84: pa_cf | E84: 3D | G84: 53.2 | H84: 174 x 100 x 94 | J84: to make
...

Sheet Actuator bolts (CAD)
A1: Actuator | B1: Face | C1: Thread | D1: Qty | E1: Notes | F1: Status
A2: RS00 | B2: output | C2: M3 | D2: 12 | E2: socket head, 12.9; length = plate + thread engagement, per part | F2: to buy
A3: RS00 | B3: stator | C3: M3 | D3: 12 | E3: socket head, 12.9; length = plate + thread engagement, per part | F3: to buy
A4: RS03 | B4: output | C4: M4 | D4: 66 | E4: socket head, 12.9; length = plate + thread engagement, per part | F4: to buy
A5: RS03 | B5: stator | C5: M4 | D5: 88 | E5: socket head, 12.9; length = plate + thread engagement, per part | F5: to buy
A6: RS04 | B6: output | C6: M5 | D6: 54 | E6: socket head, 12.9; length = plate + thread engagement, per part | F6: to buy
A7: RS04 | B7: stator | C7: M4 | D7: 60 | E7: socket head, 12.9; length = plate + thread engagement, per part | F7: to buy
A8: RS06 | B8: output | C8: M4 | D8: 24 | E8: socket head, 12.9; length = plate + thread engagement, per part | F8: to buy
A9: RS06 | B9: stator | C9: M3 | D9: 32 | E9: socket head, 12.9; length = plate + thread engagement, per part | F9: to buy
